<?xml version="1.0" ?>
 
<robot name="my_robot" xmlns:xacro="https://www.ros.org/wiki/xacro" >
  <!--import plugin gazebo-->
  <xacro:include filename="$(find my_robot)/urdf/my_robot.gazebo" />

  <!--Link (robot_footprint)-->
  <link name="robot_footprint"></link>

  <!--Joint (robot_footprint)-->
  <joint name="robot_footprint_joint" type="fixed">
    <origin xyz="0 0 0" rpy="0 0 0" />
    <parent link="robot_footprint"/>
    <child link="chassis" />
  </joint>
  
  <!--Link (chasiss)-->
  <link name="chassis">
    <pose>0 0 0.1 0 0 0</pose>

    <inertial>
      <mass value="15.0"/>
      <origin xyz="0.0 0 0" rpy=" 0 0 0"/>
      <inertia
          ixx="0.1" ixy="0" ixz="0"
          iyy="0.1" iyz="0"
          izz="0.1"
      />
    </inertial>

    <collision name='collision'>
      <origin xyz="0 0 0" rpy=" 0 0 0"/> 
      <geometry>
        <box size=".4 .2 .1"/>
      </geometry>
    </collision>

    <visual name='chassis_visual'>
      <origin xyz="0 0 0" rpy=" 0 0 0"/>
      <geometry>
        <box size=".4 .2 .1"/>
      </geometry>
    </visual>


    <collision name='back_caster_collision'>
      <origin xyz="-0.15 0 -0.05" rpy=" 0 0 0"/>
      <geometry>
        <sphere radius="0.0499"/>
      </geometry>
    </collision>

    <visual name='back_caster_visual'>
      <origin xyz="-0.15 0 -0.05" rpy=" 0 0 0"/>
      <geometry>
        <sphere radius="0.05"/>
      </geometry>
    </visual>

    <collision name='front_caster_collision'>
      <origin xyz="0.15 0 -0.05" rpy=" 0 0 0"/>
      <geometry>
        <sphere radius="0.0499"/>
      </geometry>
    </collision>

    <visual name='front_caster_visual'>
      <origin xyz="0.15 0 -0.05" rpy=" 0 0 0"/>
      <geometry>
        <sphere radius="0.05"/>
      </geometry>
    </visual>
  </link>
   <!-- this is the right wheel link-->

  <link name='r_wheel'>
    
    <collision name='right_wheel_collision'>
     <origin xyz='0 0 0' rpy='0 1.5707 1.5707'/>
     <geometry>
      	<cylinder radius= '0.1' length= '0.05'/>
     </geometry>

    </collision>

    <visual name='right_wheel_visual'>
      <origin xyz='0 0 0' rpy='0 1.5707 1.5707'/>
      <geometry>
        <cylinder radius= '0.1' length= '0.05'/>
      </geometry>
    </visual>

    <inertial>
     <geometry>
	      <cylinder radius= '0.1' length= '0.05'/>
      </geometry>
      <origin xyz='0 0 0' rpy='0 1.5707 1.5707'/>
      <mass value='5'/>
      <inertia ixx="0.1" ixy="0" ixz="0" iyy="0.1" iyz="0" izz="0.1"/>  
    </inertial>

  </link>
   
  <!--joint right wheel-->
  <joint type="continuous" name="right_wheel_joint">
    <origin xyz="0 -0.15 0" rpy="0 0 0"/>
    <child link="r_wheel"/>
    <parent link="chassis"/>
    <axis xyz="0 1 0" rpy="0 0 0"/>
    <limit effort="10000" velocity="1000"/>
    <dynamics damping="1.0" friction="1.0"/>
  </joint>

   <!-- this is the left wheel link-->

  <link name='l_wheel'>
    
    <collision name='left_wheel_collision'>
      <geometry>
	      <cylinder radius= '0.1' length= '0.05'/>
      </geometry>
      <origin xyz='0 0 0' rpy='0 1.5707 1.5707'/>
    </collision>

    <visual name='left_wheel_visual'>
      <geometry>
	        <cylinder radius= '0.1' length= '0.05'/>
      </geometry>
      <origin xyz='0 0 0' rpy='0 1.5707 1.5707'/>
    </visual>

    <inertial>
      <geometry>
	       <cylinder radius= '0.1' length= '0.05'/>
      </geometry>
      <origin xyz='0 0 0' rpy='0 1.5707 1.5707'/>
      <mass value='5'/>
      <inertia ixx="0.1" ixy="0" ixz="0" iyy="0.1" iyz="0" izz="0.1"/>  
    </inertial>

  </link>
<!--Joint (left_wheel_hinge)-->
  <joint name="right_wheel_hinge" type="continuous">
    <origin xyz="-0.05 0.15 0" rpy="0 0 0"/>
    <child link="l_wheel" />
    <parent link="chassis"/>
    <axis rpy="0 0 0" xyz="0 1 0"/>
    <limit effort="10000" velocity="1000"/>
    <joint_properties damping="1.0" friction="1.0" />
  </joint>

  <!--Link (camera)-->
  <link name='camera'>
    <inertial>
      <origin xyz="0 0 0" rpy="0 0 0"/>
      <mass value="0.1"/>
      <box_inertia m="0.1" x="0.05" y="0.05" z="0.05"/>
      <inertia
          ixx="1e-6" ixy="0" ixz="0"
          iyy="1e-6" iyz="0"
          izz="1e-6"
      />
    </inertial>

    <visual name='camera_visual'>
      <origin xyz="0 0 0" rpy="0 0 0"/>
      <geometry>
        <box size=".05 .05 .05"/>
      </geometry>
    </visual>

    <collision name='camera_collision'>
      <origin xyz="0 0 0" rpy="0 0 0"/>
      <geometry>
        <box size=".05 .05 .05"/>
      </geometry>
    </collision>
  </link>

  <!--Joint (camera)-->
  <joint type="fixed" name="camera_joint">
    <origin xyz="0.25 0 0" rpy="0 0 0"/>
    <child link="camera"/>
    <parent link="chassis"/>
    <axis xyz="0 1 0"/>
  </joint>

  <!--Links (hokuyo)-->
  <link name='hokuyo'>
    <inertial>
      <origin xyz="0 0 0" rpy="0 0 0"/>
      <mass value="1e-5"/>
      <inertia
          ixx="1e-6" ixy="0" ixz="0"
          iyy="1e-6" iyz="0"
          izz="1e-6"
      />
    </inertial>

    <visual name='hokuyo_visual'>
      <origin xyz="0 0 0" rpy="0 0 0"/>
      <geometry>
        <mesh filename="package://my_robot/meshes/hokuyo.dae"/>
      </geometry>
    </visual>

    <collision name='hokuyo_collision'>
      <origin xyz="0 0 0" rpy="0 0 0"/>
      <geometry>
        <box size=".1 .1 .1"/>
      </geometry>
    </collision>
  </link>

  <!--Joint (hokuyo)-->
  <joint type="fixed" name="hokuyo_joint">
    <origin xyz="0.15 0 .1" rpy="0 0 0"/>
    <child link="hokuyo"/>
    <parent link="chassis"/>
    <axis xyz="0 1 0"/>
  </joint>
  
   <!--give your robot some color-->
  <gazebo reference="chassis">
    <material>Gazebo/TurquoiseGlowOutline</material>
  </gazebo>

  <gazebo reference="l_wheel">
    <material>Gazebo/Wood</material>
  </gazebo>

  <gazebo reference="r_wheel">
    <material>Gazebo/Wood</material>
  </gazebo>

  <gazebo reference="camera">
    <material>Gazebo/RedBright</material>
  </gazebo>

  <gazebo reference="hokuyo">
    <material>Gazebo/Purple</material>
  </gazebo>    



</robot>
